Workbook

Sheet How to review
A1: Golden questions: review sheet
A3: What this is | B3: These questions test the Loan Copilot's answers. Each approved row becomes an automatic test that runs whenever the documents, the model or the prompt change. Your reference answer is what the app is checked against, so it must be correct and current.
A4: What to do | B4: Go through the 160 rows on the 'Questions' sheet. Fill in the yellow columns only. Grey columns are information. Blue italic text is a guess from Claude: confirm it or correct it.
A6: Column | B6: How to fill it
A7: Should the app answer? | B7: Answer: the documents contain the answer. Not found: they don't, and the app must say so rather than guess. Ask for details: the question is too vague, and the app should ask what it needs.
A8: Reference answer | B8: The correct answer as you would give it to a partner, from the current documents. Include every key figure, condition and contact. Leave empty for 'Not found'. For 'Ask for details', write what the app should ask.
A9: Must contain | B9: Optional. One exact value the answer must include (a phone number, code, % or amount), copied exactly as the document writes it.
A10: Expected document | B10: The document the answer should come from (title or file name). Pre-filled guesses are blue.
A11: Expected page | B11: Optional. Page number, for PDFs.
A12: Reviewed by | B12: Your name. Required for the row to be imported.
A13: Approved? | B13: Yes: import this row as a test. No: drop the question. Needs change: you edited the question itself, so check it again.
A14: Reviewer notes | B14: Anything useful: where the answer differs between documents, when it expires, etc.
A15: Current app answer | B15: What the app last answered (not checked). If it is right, you can copy it into the Reference answer. Do not trust it without checking the document.
A17: Example row
A18: Question | B18: Who is the home loan RM for Bajaj Finserv in Pune?
A19: Should the app answer? | B19: Answer
A20: Reference answer | B20: Chetan Rathod, 9604454809 (Pan India RM list, August 2026).
A21: Must contain | B21: 9604454809
A22: Expected document | B22: Pan India RM list Aug
A23: Reviewed by / Approved? | B23: (your name) / Yes
A25: When done | B25: Send the file back. It is loaded with: python -m evals.import_golden_review

Sheet Questions
A1: ID | B1: Category | C1: Question | D1: Earlier questions (follow-ups) | E1: Loan type | F1: Origin | G1: Current app answer (not checked) | H1: Should the app answer? | I1: Reference answer | J1: Must contain | K1: Expected document | L1: Expected page | M1: Reviewed by | N1: Approved? | O1: Reviewer notes
A2: G001 | B2: banker | C2: Who is the home loan RM for Bajaj Finserv in Pune? | F2: seed | G2: **Home‑Loan Relationship Managers (RMs) for Bajaj Finserv in Pune** | Lender | RM / Banker | Contact No. | Loan Type | |--------|-------------|------------|-----------| | Bajaj Finserv | Chetan Rathod | 9604454809 | Home Loan | | Bajaj Finserv | Omkar Kadam | 8803032727 | Home Loan | | Bajaj Finserv | Rupesh Nawalkar | 8983530408 | Home Loan | | Bajaj Finserv | SWAPNIL BORADE | 9158261188 | Home Loan | | Bajaj Finserv | lokendra bhadoriya | 8087730020 | Home Loan | | Bajaj Finserv | Rahul Chopde | 9096887881 | Home Loan | | Bajaj Finserv | sachin patil | 9422242332 | Home Loan | | Bajaj Finserv | Sagar Sable | 8080376527 | Home Loan | | Bajaj Finserv | SANDIP SHARMA | 8828529503 | Home Loan | | Bajaj Finserv | Prem Prakash | 9881241106 | Home Loan | *Sources:* Home‑Loan bankers at Bajaj Finserv in Pune from the app’s de‑duplicated list – first 10 shown out of 321 distinct bankers [S1][S2]. | J2: 9604454809 | K2: Pan India RM list Aug
A3: G002 | B3: banker | C3: give me sbi rm list in pune location for home loan | F3: seed | G3: **State Bank of India – Pune (Home Loan) Relationship Managers** | Banker / RM | Contact No. | Source | |------------|------------|--------| | Pankaj | 9923000545 | [S1] | | Amol Dhawade | 9881285428 | [S2] | | Chetan Singh | 7030485392 | [S2] | | AMITA | 9167243941 | [S2] | | Deepa Rao | 8055469504 | [S2] | | Divya Shaji | 8329269674 | [S2] | | harshal sir | 8983661292 | [S2] | | Krishna Sonawane | 7745025654 | [S2] | | Krushna Sonawane | 7745025654 | [S2] | | KULDEEP | 9960553770 | [S2] | *The app’s matching process identified **26 distinct Home Loan bankers** for SBI in Pune; the table above shows the best 10 currently displayed across the available lists.* | J3: 9923000545 | K3: Pan India RM list Aug
A4: G003 | B4: banker | C4: HDFC Bank business loan RM list in Pune | F4: seed | G4: **HDFC Bank – Business Loan Relationship Managers (RM) in Pune (top 10 shown)** | Lender | Banker / RM | Contact No | Note | |--------|-------------|------------|------| | HDFC Bank | Rahul Metkar | 9673696000 | Business Loan |【S1】 | | HDFC Bank | Sanskruti Choudha | 7383873628 | Business Loan |【S2】 | | HDFC Bank | Akhil Shrivastava | 9284002925 | Business Loan |【S3】 | | HDFC Bank | Sasmit Bhat | 7028636292 | Business Loan |【S3】 | | HDFC Bank | Abhishek | 9511819127 | Business Loan |【S3】 | | HDFC Bank | ajay | 8596471325 | Business Loan |【S3】 | | HDFC Bank | AMIT | 8828062605 | Business Loan |【S3】 | | HDFC Bank | AMIT SINGH | 8828062605 | Business Loan |【S3】 | | HDFC Bank | AMOL HAKE | 9601236540 | Business Loan |【S3】 | | HDFC Bank | GAURAV KR. SINHA | 9334251120 | Business Loan |【S3】 | *The app’s filter identified **42 distinct Business Loan bankers** for HDFC Bank in Pune; the table above shows the best 10 currently displayed.* | J4: 9673696000 | K4: Pan India RM list Aug
A5: G004 | B5: banker | C5: Kotak LAP RM contact in Bangalore | F5: seed | G5: **Kotak Mahindra Bank – LAP Relationship Managers (Bangalore)** | RM / Banker | Contact No. | Source | |-------------|------------|--------| | Mani | 9080635135 | [S1] | | Manjunatha K A | 8123041571 | [S1] | | praveen naik | 7892107583 | [S1] | | Umarathi J | 9152763409 | [S1] | | manjunath | 8123041571 | [S2] | | Anil Rana | 8114807584 | [S3] | | nagaraj | 7349525248 | [S3] | | Rajeev Singh | 9953961635 | [S3] | | sultanahmed | 8197064546 | [S3] | These are the LAP‑type loan relationship managers for Kotak Mahindra Bank in Bangalore, as listed in the current internal RM lists. | J5: 8123041571 | K5: Pan India RM list Aug
A6: G005 | B6: banker | C6: ICICI Bank home loan banker in Mumbai | F6: seed | G6: **ICICI Bank – Home Loan bankers in Mumbai (top 10 shown out of 418 matched)** | Lender | Banker / RM | Contact No. | Type of Loan | |--------|-------------|------------|--------------| | ICICI Bank | adarsh singh | 9762819619 | Home Loan | | ICICI Bank | Bipin Bharti | 9594421307 | Home Loan | | ICICI Bank | muskan sinha | 8591969918 | Home Loan | | ICICI Bank | Renuka Patil | 9326068468 | HLUC | | ICICI Bank | sujeet | 8356865642 | Home Loan | | ICICI Bank | vijay kamble | 7738193822 | Home Loan | | ICICI Bank | AARTI | 8655861232 | Home Loan | | ICICI Bank | amrish | 9892807025 | Home Loan | | ICICI Bank | ANIL PAWAR | 9372137064 | Home Loan | | ICICI Bank | ANUP DUBEY | 7977770181 | Home Loan | *The list is derived from the app’s de‑duplicated match of **418 distinct bankers** for ICICI Bank home loans in Mumbai; the table shows the best 10 entries. [S1]* | J6: 9762819619 | K6: Pan India RM list Aug
A7: G006 | B7: banker | C7: Axis Bank personal loan RM in Delhi | F7: seed | G7: **Axis Bank – Personal Loan Relationship Managers (RM) in Delhi** | Lender | Banker / RM | Contact No. | Type of Loan | |--------|-------------|------------|--------------| | Axis Bank | Rajesh Kumar Mahto | 9354439591 | Personal Loan | [S1] | | Axis Bank | riya gupta | 9811391057 | Personal Loan | [S1] | | Axis Bank | Raju Bharti | 8130991534 | Personal Loan | [S1] | | Axis Bank | SATISH | 9717960530 | Personal Loan | [S1] | | Axis Bank | SHUBHAM | 9716333332 | Personal Loan | [S1] | | Axis Bank | ANKIT | 8802302715 | Personal Loan | [S1] | | Axis Bank | ANUJ KUMAR | 8874443636 | Personal Loan | [S1] | | Axis Bank | Surendra Kumar | 7053086357 | Personal Loan | [S1] | | Axis Bank | SWATI | 8368960123 | Personal Loan | [S1] | | Axis Bank | SUBHAM RASTOGI | 9716333332 | Personal Loan | [S2] | These are the personal‑loan RMs for Axis Bank in Delhi as provided by the latest internal banker‑match lists. | J7: 9354439591 | K7: Pan India RM list Aug
A8: G007 | B8: banker | C8: Tata Capital LAP RM in Bangalore | F8: seed | G8: **Tata Capital – LAP Relationship Managers (Bangalore)** | Lender | Banker / RM | Contact No | Note | |--------|-------------|------------|------| | Tata Capital | BHOLA PAUL | 7004156167 | | | Tata Capital | CHANDAN | 9538435826 | verify: also listed as 8050510970 | | Tata Capital | PRASANNA | 8123890788 | | | Tata Capital | Abhishek Kumar | 9986100788 | Top Up‑LAP; verify: also listed as 18390836437 | | Tata Capital | Prathap | 9353829445 | LAP‑DoD | | Tata Capital | SANKETHA | 7892990188 | | | Tata Capital | MANOJ G | 9019979273 | | | Tata Capital | Appayya | 9035814193 | | | Tata Capital | AYUSH VERMA | 7761021345 | | | Tata Capital | Ravi | 9742551551 | | *All 10 RMs are for the LAP product in Bangalore.* Sources: BHOLA PAUL, CHANDAN, PRASANNA, Abhishek Kumar – [S1]; Prathap, SANKETHA, MANOJ G, Appayya, AYUSH VERMA, Ravi – [S2]. | J8: 7004156167 | K8: Pan India RM list Aug
A9: G008 | B9: banker | C9: Aditya Birla home loan RM contact Pune | F9: seed | G9: **Aditya Birla Capital – Home Loan Relationship Managers (Pune)** | Banker / RM | Contact No | Note | |---|---|---| | Atul More | 7620750095 | | | Santosh Chavan | 8329702008 | | | Suhas Mane | 9561125000 | | | deepak mishra | 7378770503 | | | Kamlesh Ahirrao | 9766043194 | | | Kishor Nawale | 9822652832 | | | AMOL MEHTA | 626709040 | verify: also listed as 6267090402 | | Gajanan Gundale | 9588604690 | | | Shubham Gaikwad | 8482909907 | | | Ajinkya Shinde | 7972199236 | | *These are the Home Loan bankers for Aditya Birla Capital in Pune as provided by the latest internal RM list (99 distinct bankers matched, best 10 shown).* Sources: Atul More – Santosh Chavan – Suhas Mane – deepak mishra – Kamlesh Ahirrao – Kishor Nawale [S1]; AMOL MEHTA – Gajanan Gundale – Shubham Gaikwad – Ajinkya Shinde [S2]. | J9: 9561125000 | K9: Pan India RM list Aug
A10: G009 | B10: banker | C10: IDFC First personal loan RM in Mumbai | F10: seed | G10: **IDFC First Bank – Personal Loan Relationship Managers (Mumbai)** | Banker / RM | Contact No. | |-------------|------------| | ajay yadav | 8779326728 | | AKSHAY BHOSALE | 9967342695 | | gaurav pandey | 8369995329 | | Prabhat Trivedi | 8779285394 | | sarvesh ghadi | 8828501927 | | Prabhat | 8779285394 | | PRACHI TIWARI | 8104071500 | | RUPESH | 8879485695 | | SATISH NISHAD | 8767298241 | *These are the top personal‑loan bankers for IDFC First Bank in Mumbai, selected from a pool of 91 distinct bankers (the best 10 shown). The information comes from the internal banker‑match list [S1].* *Note:* An additional entry “AKSHAY” with the same contact number appears in a second list [S2]; it corresponds to “AKSHAY BHOSALE” shown above. | J10: 8779326728 | K10: Pan India RM list Aug
A11: G010 | B11: banker | C11: L&T Finance home loan RM Mumbai | F11: seed | G11: **L&T Finance – Home Loan Relationship Managers (Mumbai)** | Lender | Banker / RM | Contact No. | Note | |--------|-------------|------------|------| | L&T Finance | Kundan Gupta | 7355955100 | Home Loan 【S1】 | | L&T Finance | PREM GUPTA | 9670912892 | Home Loan 【S1】 | | L&T Finance | Anil Vishwakarma | 9867744879 | Home Loan 【S1】 | | L&T Finance | MAHESH | 9029461618 | Home Loan 【S1】 | | L&T Finance | Anil Maurya | 7355032451 | Home Loan 【S2】 | These are the Home Loan RMs for L&T Finance in Mumbai as provided in the active banker‑match lists. | J11: 7355955100 | K11: Pan India RM list Aug
A12: G011 | B12: banker | C12: Canara Bank home loan RM in Ahmedabad | F12: seed | G12: **Canara Bank – Home Loan Relationship Managers (RM) in Ahmedabad** | Lender | Banker / RM | Contact No. | Note | |--------|-------------|-------------|------| | Canara Bank | VIJAY SRIVASTAVA | 8318809724 | | | Canara Bank | AVANEESH KUMAR PANDEY | 9099909324 | verify: also listed as 8238091910 | | Canara Bank | Deshraj | 9427314768 | | | Canara Bank | Gaurav Kumar | 8370848862 | | | Canara Bank | HIMANSHU KATARIA | 8059629629 | | | Canara Bank | Sunil Kumar | 6358365044 | | | Canara Bank | VARTIKA SINGH | 8238091903 | | | Canara Bank | AMAN JOSHI | 8238091930 | | | Canara Bank | ABHISHEK KHARE | 9003587162 | Designation: RAH HEAD NAME; verify: also listed as 8511999564 | *Source: [S1]* | Lender | Banker / RM | Contact No. | Note | |--------|-------------|-------------|------| | Canara Bank | ANANT KHILNANI | 95996641539 | verify number | *Source: [S2]* | J12: 9099909324 | K12: Pan India RM list Aug
A13: G012 | B13: banker | C13: Piramal LAP banker contact in Pune | F13: seed | G13: **Piramal Finance – LAP bankers in Pune (contact numbers)** | Banker (LAP) | Contact No. | Source | |--------------|------------|--------| | Shubham Patil | 9595966202 | [S1] | | Akshay Chavhan | 8766884343 | [S1] | | AMOL KHOPADE | 9623036036 | [S1] | | JAYANT KULKARNI | 9172627284 | [S1] | | MADAN KUMAR | 9631922668 | [S1] | | CHANDRAKANT YADAV | 9284587800 | [S2] | | Amit Belbhare | 8551812525 | [S3] | | ABULWAFA SHAIKH | 9545258464 | [S4] | | Amit Bailbhare | 9881802331 *(also listed as 8551812525)* | [S4] | | Komal Domewale | 9022132408 | [S4] | *The list reflects the best‑matched 10 LAP bankers for Piramal Finance in Pune (out of 63 distinct bankers matched).​* | J13: 9595966202 | K13: Pan India RM list Aug
... A31: G030 | B31: policy | C31: Aditya Birla STSL LAP RSM contact number | F31: seed | G31: **RSM contact number:** **9049000381** **Details** - The RSM for Aditya Birla STSL LAP is Rahul Vyas, and his phone number is **9049000381**【S1】【S4】. | J31: 9049000381 | K31: Aditya Birla STSL LAP Reference
A32: G031 | B32: policy | C32: How does interest work on the Flexi business loan? | F32: seed | G32: I couldn't find this information in the available knowledge base. Please ask the administrator to add or update the relevant source document. | K32: FAQs Flexi BL
A33: G032 | B33: pincode | C33: Is pincode 400006 serviceable for Fibe? | F33: seed | G33: **Yes, pincode 400006 is serviceable for Fibe.** - The Fibe active pincode list includes **400006** among the serviceable area pincodes【S1】. (For reference, the SME serviceable list also marks 400006 as Offline + Digital, but the Fibe list alone confirms its serviceability.) | J33: 400006 | K33: fibe pincode list
A34: G033 | B34: outdated | C34: Bajaj Finserv home loan RM in Pune from the latest RM list | F34: seed | G34: I couldn't find this information in the available knowledge base. Please ask the administrator to add or update the relevant source document. | J34: 9604454809 | K34: Pan India RM list Aug
A35: G034 | B35: outdated | C35: Latest Kotak Mahindra machinery loan code | F35: seed | G35: **Latest Kotak Mahindra machinery loan code:** **171504070** **Details** - Product: **Industrial Machine / Medical Equipments** - Bank: Kotak Mahindra (Kotak Mahindra Bank) - Code in name: **URBAN MONEY** This code appears in the most recent “215 PLUS CODES AND CONTACT DETAILS” (April 2026) spreadsheet and also in the earlier “AUG 26 – CODES AND CONTACTS” file, both showing the same value **171504070**【S2】【S1】. | J35: 171504070 | K35: AUG 26 - CODES AND CONTACTS
A36: G035 | B36: missing | C36: What is the home loan payout for Zentrix Housing Finance? | F36: seed | G36: I couldn't find this information in the available knowledge base. Please ask the administrator to add or update the relevant source document. | H36: Not found
A37: G036 | B37: missing | C37: Zentrix Housing Finance RM contact in Pune | F37: seed | G37: I couldn't find this information in the available knowledge base. Please ask the administrator to add or update the relevant source document. | H37: Not found
A38: G037 | B38: missing | C38: What is the gold loan ROI for Zentrix Bank? | F38: seed | G38: I couldn't find this information in the available knowledge base. Please ask the administrator to add or update the relevant source document. | H38: Not found
A39: G038 | B39: profile | C39: Salaried customer, net salary ₹1,45,000 per month, no existing EMIs, CIBIL 845, wants a ₹98 lakh home loan for a flat in Pune. Give banker list in Pune. | E39: Home Loan | F39: seed | G39: Salaried customer earning **₹1,45,000** / month, CIBIL 845, seeking a **₹98 lakh** home loan for a flat in **Pune** – the following lenders/RMs are the best matches in the knowledge base. ### Customer Profile | Field | Details | |---|---| | Loan Type | Home Loan | | Employment | Salaried customer | | Monthly Income | ₹1,45,000 | | Required Loan | ₹98 lakh | | CIBIL | 845 | | Existing EMI | None | | Property Location | Pune | | Other | flat; banker list in Pune | ### Eligibility Snapshot | Metric | Value | |---|---:| | Monthly Income | ₹1,45,000 | | Existing EMI | ₹0 | | FOIR (app policy) | 55% | | Interest Rate | 8.75% (app default) | | Tenure | 25 years (app default) | | EMI Capacity | ₹79,750 | | Requested Loan | ₹98,00,000 | | Requested Loan EMI | ₹80,570 | | Indicative Maximum Loan | ₹97,00,251 | Based on the application's indicative calculation, the requested loan amount is **above indicative eligibility by ₹99,749 (EMI ₹80,570 vs capacity ₹79,750)**. Final approval depends on the lender's underwriting and policy. ### Bankers / Lenders to Approach — Pune | # | Bank / Lender | Banker / RM | Phone | Match | |---|---|---|---|---| | 1 | Bajaj Finserv | Chetan Rathod [S1] | …(cut; full answer in Admin > RAG quality) | J39: 79,750 | K39: Pan India RM list Aug
A40: G039 | B40: profile | C40: Customer earns 18 LPA, salaried, no EMIs, needs 60 lakh home loan in Mumbai, CIBIL 790. Which bankers should I approach? | E40: Home Loan | F40: seed | G40: Salaried, 18 LPA annual income, CIBIL 790, seeking ₹60 lakh home loan in Mumbai – the following bankers are the best matches. ### Customer Profile | Field | Details | |---|---| | Loan Type | Home Loan | | Employment | salaried | | Monthly Income | Not provided | | Required Loan | 60 lakh | | CIBIL | 790 | | Existing EMI | None | | Property Location | Mumbai | | Annual Income | 18 LPA | ### Eligibility Snapshot | Metric | Value | |---|---:| | Monthly Income | ₹1,50,000 | | Existing EMI | ₹0 | | FOIR (app policy) | 55% | | Interest Rate | 8.75% (app default) | | Tenure | 25 years (app default) | | EMI Capacity | ₹82,500 | | Requested Loan | ₹60,00,000 | | Requested Loan EMI | ₹49,329 | | Indicative Maximum Loan | ₹1,00,34,743 | Based on the application's indicative calculation, the requested loan amount is **within indicative eligibility (EMI ₹49,329 vs capacity ₹82,500)**. Final approval depends on the lender's underwriting and policy. ### Bankers / Lenders to Approach — Mumbai | # | Bank / Lender | Banker / RM | Phone | Match | |---|---|---|---|---| | 1 | Canara Bank | PRAVEEN KUMAR [S1] | 9500429774 (verify: also listed as 9326446868) | Strong | | 2 | ICICI Bank | adarsh …(cut; full answer in Admin > RAG quality) | J40: 1,50,000 | K40: Pan India RM list Aug
A41: G040 | B41: profile | C41: Salaried, ₹90,000 a month, EMI ₹15,000, wants ₹30 lakh LAP. CIBIL 760. Suggest bankers. | F41: seed | G41: I can list the bankers to approach once I know a little more. ### Customer Profile | Field | Details | |---|---| | Loan Type | LAP | | Employment | Salaried | | Monthly Income | ₹90,000 a month | | Required Loan | ₹30 lakh | | CIBIL | 760 | | Existing EMI | ₹15,000 | | Property Location | Not provided | ### Eligibility Snapshot | Metric | Value | |---|---:| | Monthly Income | ₹90,000 | | Existing EMI | ₹15,000 | | FOIR (app policy) | 60% | | Interest Rate | 10% (app default) | | Tenure | 15 years (app default) | | EMI Capacity | ₹39,000 | | Requested Loan | ₹30,00,000 | | Requested Loan EMI | ₹32,238 | | Indicative Maximum Loan | ₹36,29,240 | ### Needed to list bankers - the city where the property is or the loan is needed Reply with these details and I'll match the bankers from the latest RM lists. | J41: the city where the property is
A42: G041 | B42: profile | C42: Self-employed doctor, income 2 lakh per month, existing EMI 40k, needs 50 lakh home loan in Bangalore, CIBIL 780. Which lenders should I approach? | E42: Home Loan | F42: seed | G42: Self‑employed doctor, ₹2 lakh monthly income, CIBIL 780, seeking ₹50 lakh home loan in Bangalore – the following lenders/RMs are the best matches. ### Customer Profile | Field | Details | |---|---| | Loan Type | Home Loan | | Employment | Self‑employed doctor | | Monthly Income | 2 lakh per month | | Required Loan | 50 lakh | | CIBIL | 780 | | Existing EMI | 40k | | Property Location | Bangalore | ### Eligibility Snapshot | Metric | Value | |---|---:| | Monthly Income | ₹2,00,000 | | Existing EMI | ₹40,000 | | FOIR (app policy) | 55% | | Interest Rate | 8.75% (app default) | | Tenure | 25 years (app default) | | EMI Capacity | ₹70,000 | | Requested Loan | ₹50,00,000 | | Requested Loan EMI | ₹41,107 | | Indicative Maximum Loan | ₹85,14,327 | Based on the application's indicative calculation, the requested loan amount is **within indicative eligibility (EMI ₹41,107 vs capacity ₹70,000)**. Final approval depends on the lender's underwriting and policy. ### Bankers / Lenders to Approach — Bangalore | # | Bank / Lender | Banker / RM | Phone | Match | |---|---|---|---|---| | 1 | Bajaj Finserv | Ajith N [S1] | 7619282678 | Strong | | 2 | ICICI Bank | BIDHAN [S1] | 7022775622 | Strong …(cut; full answer in Admin > RAG quality) | J42: 70,000 | K42: Pan India RM list Aug
A43: G042 | B43: policy | C43: What is the FOIR limit in HDFC Bank's new Xpress Personal Loan policy? | E43: Personal Loan | F43: drafted | K43: HDFC Bank Xpress Personal Loan - New FOIR Policy
A44: G043 | B44: policy | C44: Does the HDFC Xpress personal loan FOIR change with the customer's salary? | E44: Personal Loan | F44: drafted | K44: HDFC Bank Xpress Personal Loan - New FOIR Policy
A45: G044 | B45: policy | C45: What is the maximum loan-to-value for the South Indian Bank GEMS car loan? | E45: Car Loan | F45: drafted | K45: South Indian Bank GEMS Car Loan Policy
A46: G045 | B46: policy | C46: Minimum income required for the South Indian Bank GEMS car loan? | E46: Car Loan | F46: drafted | K46: South Indian Bank GEMS Car Loan Policy
A47: G046 | B47: policy | C47: What is South Indian Bank's car loan interest rate? | E47: Car Loan | F47: drafted | K47: South Indian Bank Car Loan Interest Rate Guidance
A48: G047 | B48: policy | C48: What are the variants of the Chola unsecured business loan? | E48: Business Loan | F48: drafted | K48: Chola Unsecured Business Loan Product Variants and Norms
A49: G048 | B49: policy | C49: Minimum business vintage for a Chola unsecured business loan? | E49: Business Loan | F49: drafted | K49: Chola Unsecured Business Loan Product Variants and Norms
A50: G049 | B50: policy | C50: Maximum loan amount for a doctor under the Chola CSEL professional loan? | E50: Professional Loan | F50: drafted | K50: Chola CSEL Professional Loan Ready Reckoner
A51: G050 | B51: policy | C51: Minimum turnover for a Standard Chartered unsecured business loan? | E51: Business Loan | F51: drafted | K51: Standard Chartered Bank Unsecured Business Loan Policy Poster
A52: G051 | B52: policy | C52: What ROI does Standard Chartered offer on unsecured business loans? | E52: Business Loan | F52: drafted | K52: Standard Chartered Bank Unsecured Business Loan Policy Poster
A53: G052 | B53: policy | C53: What changed in the latest Credit Saison India policy update? | F53: drafted | K53: Credit Saison India Policy Updates
A54: G053 | B54: policy | C54: Minimum CIBIL score for an Aavas Financiers home loan? | E54: Home Loan | F54: drafted | K54: Aavas Financiers Policy Poster
A55: G054 | B55: policy | C55: Who is eligible under the LTP degree surrogate program? | F55: drafted | K55: LTP - Degree Surrogate - One pager policy V1
A56: G055 | B56: policy | C56: Maximum loan amount in the LTP one pager policy? | F56: drafted | K56: LTP - One Pager policy V1
A57: G056 | B57: policy | C57: Minimum business vintage in the BL one pager policy V2? | E57: Business Loan | F57: drafted | K57: BL - One Pager Policy V2
...

Sheet Progress
A1: Category | B1: Questions | C1: Reviewed | D1: Approved | E1: Not found expected | F1: Approved %
A2: banker | B2: =COUNTIF('Questions'!$B$2:$B$161,A2) | C2: =COUNTIFS('Questions'!$B$2:$B$161,A2,'Questions'!$M$2:$M$161,"<>") | D2: =COUNTIFS('Questions'!$B$2:$B$161,A2,'Questions'!$N$2:$N$161,"Yes") | E2: =COUNTIFS('Questions'!$B$2:$B$161,A2,'Questions'!$H$2:$H$161,"Not found") | F2: =IF(B2=0,0,D2/B2)
A3: alias | B3: =COUNTIF('Questions'!$B$2:$B$161,A3) | C3: =COUNTIFS('Questions'!$B$2:$B$161,A3,'Questions'!$M$2:$M$161,"<>") | D3: =COUNTIFS('Questions'!$B$2:$B$161,A3,'Questions'!$N$2:$N$161,"Yes") | E3: =COUNTIFS('Questions'!$B$2:$B$161,A3,'Questions'!$H$2:$H$161,"Not found") | F3: =IF(B3=0,0,D3/B3)
A4: code | B4: =COUNTIF('Questions'!$B$2:$B$161,A4) | C4: =COUNTIFS('Questions'!$B$2:$B$161,A4,'Questions'!$M$2:$M$161,"<>") | D4: =COUNTIFS('Questions'!$B$2:$B$161,A4,'Questions'!$N$2:$N$161,"Yes") | E4: =COUNTIFS('Questions'!$B$2:$B$161,A4,'Questions'!$H$2:$H$161,"Not found") | F4: =IF(B4=0,0,D4/B4)
A5: payout | B5: =COUNTIF('Questions'!$B$2:$B$161,A5) | C5: =COUNTIFS('Questions'!$B$2:$B$161,A5,'Questions'!$M$2:$M$161,"<>") | D5: =COUNTIFS('Questions'!$B$2:$B$161,A5,'Questions'!$N$2:$N$161,"Yes") | E5: =COUNTIFS('Questions'!$B$2:$B$161,A5,'Questions'!$H$2:$H$161,"Not found") | F5: =IF(B5=0,0,D5/B5)
A6: policy | B6: =COUNTIF('Questions'!$B$2:$B$161,A6) | C6: =COUNTIFS('Questions'!$B$2:$B$161,A6,'Questions'!$M$2:$M$161,"<>") | D6: =COUNTIFS('Questions'!$B$2:$B$161,A6,'Questions'!$N$2:$N$161,"Yes") | E6: =COUNTIFS('Questions'!$B$2:$B$161,A6,'Questions'!$H$2:$H$161,"Not found") | F6: =IF(B6=0,0,D6/B6)
A7: pincode | B7: =COUNTIF('Questions'!$B$2:$B$161,A7) | C7: =COUNTIFS('Questions'!$B$2:$B$161,A7,'Questions'!$M$2:$M$161,"<>") | D7: =COUNTIFS('Questions'!$B$2:$B$161,A7,'Questions'!$N$2:$N$161,"Yes") | E7: =COUNTIFS('Questions'!$B$2:$B$161,A7,'Questions'!$H$2:$H$161,"Not found") | F7: =IF(B7=0,0,D7/B7)
A8: outdated | B8: =COUNTIF('Questions'!$B$2:$B$161,A8) | C8: =COUNTIFS('Questions'!$B$2:$B$161,A8,'Questions'!$M$2:$M$161,"<>") | D8: =COUNTIFS('Questions'!$B$2:$B$161,A8,'Questions'!$N$2:$N$161,"Yes") | E8: =COUNTIFS('Questions'!$B$2:$B$161,A8,'Questions'!$H$2:$H$161,"Not found") | F8: =IF(B8=0,0,D8/B8)
A9: missing | B9: =COUNTIF('Questions'!$B$2:$B$161,A9) | C9: =COUNTIFS('Questions'!$B$2:$B$161,A9,'Questions'!$M$2:$M$161,"<>") | D9: =COUNTIFS('Questions'!$B$2:$B$161,A9,'Questions'!$N$2:$N$161,"Yes") | E9: =COUNTIFS('Questions'!$B$2:$B$161,A9,'Questions'!$H$2:$H$161,"Not found") | F9: =IF(B9=0,0,D9/B9)
A10: profile | B10: =COUNTIF('Questions'!$B$2:$B$161,A10) | C10: =COUNTIFS('Questions'!$B$2:$B$161,A10,'Questions'!$M$2:$M$161,"<>") | D10: =COUNTIFS('Questions'!$B$2:$B$161,A10,'Questions'!$N$2:$N$161,"Yes") | E10: =COUNTIFS('Questions'!$B$2:$B$161,A10,'Questions'!$H$2:$H$161,"Not found") | F10: =IF(B10=0,0,D10/B10)
A11: rate | B11: =COUNTIF('Questions'!$B$2:$B$161,A11) | C11: =COUNTIFS('Questions'!$B$2:$B$161,A11,'Questions'!$M$2:$M$161,"<>") | D11: =COUNTIFS('Questions'!$B$2:$B$161,A11,'Questions'!$N$2:$N$161,"Yes") | E11: =COUNTIFS('Questions'!$B$2:$B$161,A11,'Questions'!$H$2:$H$161,"Not found") | F11: =IF(B11=0,0,D11/B11)
A12: eligibility | B12: =COUNTIF('Questions'!$B$2:$B$161,A12) | C12: =COUNTIFS('Questions'!$B$2:$B$161,A12,'Questions'!$M$2:$M$161,"<>") | D12: =COUNTIFS('Questions'!$B$2:$B$161,A12,'Questions'!$N$2:$N$161,"Yes") | E12: =COUNTIFS('Questions'!$B$2:$B$161,A12,'Questions'!$H$2:$H$161,"Not found") | F12: =IF(B12=0,0,D12/B12)
A13: count | B13: =COUNTIF('Questions'!$B$2:$B$161,A13) | C13: =COUNTIFS('Questions'!$B$2:$B$161,A13,'Questions'!$M$2:$M$161,"<>") | D13: =COUNTIFS('Questions'!$B$2:$B$161,A13,'Questions'!$N$2:$N$161,"Yes") | E13: =COUNTIFS('Questions'!$B$2:$B$161,A13,'Questions'!$H$2:$H$161,"Not found") | F13: =IF(B13=0,0,D13/B13)
... A19: chat log | B19: =COUNTIF('Questions'!$B$2:$B$161,A19) | C19: =COUNTIFS('Questions'!$B$2:$B$161,A19,'Questions'!$M$2:$M$161,"<>") | D19: =COUNTIFS('Questions'!$B$2:$B$161,A19,'Questions'!$N$2:$N$161,"Yes") | E19: =COUNTIFS('Questions'!$B$2:$B$161,A19,'Questions'!$H$2:$H$161,"Not found") | F19: =IF(B19=0,0,D19/B19)
A20: Total | B20: =SUM(B2:B19) | C20: =SUM(C2:C19) | D20: =SUM(D2:D19) | E20: =SUM(E2:E19) | F20: =IF(B20=0,0,D20/B20)
A22: Counts come from the Questions sheet and update as rows are filled in.
